Workbook

Sheet Teste 2
B2: Curso de Excel do Básico ao Avançado
B5: Professor: | D5: Clevison Santos
D9: PERGUNTAS DE ENTREVISTAS E TESTES DE EXCEL
B14: >> | D14: Vá na Aba de "Dados" e crie um campo que some a Qtd, um outro que some o Preço e outro que some o Total Vendas
B19: >> | D19: Crie uma planilha que some as vendas por item, independente do periodo
B24: >> | D24: Ao lado da soma total do item, crie uma outra coluna: Caso a venda total do item (em todos os meses) seja maior que 2000, preencher esta coluna adicional com "Meta Batida", caso contrario "Em Andamento"

Sheet Dados
A1: Código Produto | B1: Produto | C1: Mês | D1: Qtd | E1: Preço | F1: Total Vendas | H1: Qtd | I1: Preço | J1: Total de vendas
A2: 14624 | B2: Panela De Pressão | C2: 44562 | D2: 45 | E2: 56.99 | F2: =D2*E2 -> 2564.55 | H2: =SUM(D2:D27) -> 762 | I2: =SUM(E2:E27) -> 5036.63 | J2: =SUM(F2:F27) -> 105013
A3: 2714 | B3: Kit 15 Tangas | C3: 44567 | D3: 23 | E3: 38.77 | F3: =D3*E3 -> 891.71
A4: 4550 | B4: Xiaomi Redmi 9 (Global) | C4: 44572 | D4: 12 | E4: 1200 | F4: =D4*E4 -> 14400
A5: 7494 | B5: Terno Slim | C5: 44577 | D5: 123 | E5: 189 | F5: =D5*E5 -> 23247
A6: 4820 | B6: Kit Bomba A Vácuo Para Vinho | C6: 44582 | D6: 20 | E6: 37.99 | F6: =D6*E6 -> 759.8
A7: 14264 | B7: Kit 120 Tangas | C7: 44587 | D7: 23 | E7: 165.6 | F7: =D7*E7 -> 3808.8
A8: 9988 | B8: Panela De Pressão 4,5litros | C8: 44593 | D8: 31 | E8: 56.99 | F8: =D8*E8 -> 1766.69
A9: 4226 | B9: Kit De Acessórios Para Banheiro | C9: 44596 | D9: 45 | E9: 49 | F9: =D9*E9 -> 2205
A10: 19160 | B10: Colchão Casal de espuma | C10: 44599 | D10: 2 | E10: 733.9 | F10: =D10*E10 -> 1467.8
A11: 17854 | B11: Moedor De Cafe Manual | C11: 44602 | D11: 4 | E11: 116.99 | F11: =D11*E11 -> 467.96
A12: 7494 | B12: Terno Slim | C12: 44604 | D12: 123 | E12: 189 | F12: =D12*E12 -> 23247
A13: 12630 | B13: LG K22 Dual SIM 32 GB | C13: 44605 | D13: 3 | E13: 999 | F13: =D13*E13 -> 2997
A14: 17608 | B14: Spray Borrifador Pulverizador | C14: 44608 | D14: 6 | E14: 34.9 | F14: =D14*E14 -> 209.4
... A27: 14624 | B27: Panela De Pressão | C27: 44674 | D27: 21 | E27: 56.99 | F27: =D27*E27 -> 1196.79
D28: =SUM(D2:D27) -> 762 | E28: =SUM(E2:E27) -> 5036.63 | F28: =SUM(F2:F27) -> 105013

Sheet Planilha1
A1: Código Produto | B1: Produto | C1: Mês | D1: Qtd | E1: Preço | F1: Total Vendas
A2: 11340 | B2: Botas Feminina Montaria | C2: 44637 | D2: 14 | E2: 149.9 | F2: =D2*E2 -> 2098.6
B3: Botas Feminina Montaria Total | D3: =SUBTOTAL(9,D2:D2) -> 14 | E3: =SUBTOTAL(9,E2:E2) -> 149.9 | F3: =SUBTOTAL(9,F2:F2) -> 2098.6
A4: 5982 | B4: Cafeteira Aluminio Extra | C4: 44629 | D4: 9 | E4: 50 | F4: =D4*E4 -> 450
B5: Cafeteira Aluminio Extra Total | D5: =SUBTOTAL(9,D4:D4) -> 9 | E5: =SUBTOTAL(9,E4:E4) -> 50 | F5: =SUBTOTAL(9,F4:F4) -> 450
A6: 2345 | B6: Caixa de ferramentas Fercar | C6: 44649 | D6: 21 | E6: 143.12 | F6: =D6*E6 -> 3005.52
B7: Caixa de ferramentas Fercar Total | D7: =SUBTOTAL(9,D6:D6) -> 21 | E7: =SUBTOTAL(9,E6:E6) -> 143.12 | F7: =SUBTOTAL(9,F6:F6) -> 3005.52
A8: 3886 | B8: Calça Jeans Feminina | C8: 44625 | D8: 45 | E8: 98.9 | F8: =D8*E8 -> 4450.5
A9: 3886 | B9: Calça Jeans Feminina | C9: 44656 | D9: 12 | E9: 98.9 | F9: =D9*E9 -> 1186.8
B10: Calça Jeans Feminina Total | D10: =SUBTOTAL(9,D8:D9) -> 57 | E10: =SUBTOTAL(9,E8:E9) -> 197.8 | F10: =SUBTOTAL(9,F8:F9) -> 5637.3
A11: 2290 | B11: Camiseta Cinta Modeladora | C11: 44641 | D11: 41 | E11: 53.99 | F11: =D11*E11 -> 2213.59
B12: Camiseta Cinta Modeladora Total | D12: =SUBTOTAL(9,D11:D11) -> 41 | E12: =SUBTOTAL(9,E11:E11) -> 53.99 | F12: =SUBTOTAL(9,F11:F11) -> 2213.59
A13: 5740 | B13: Camiseta Regata | C13: 44611 | D13: 34 | E13: 53.91 | F13: =D13*E13 -> 1832.94
A14: 5740 | B14: Camiseta Regata | C14: 44634 | D14: 12 | E14: 53.91 | F14: =D14*E14 -> 646.92
B15: Camiseta Regata Total | D15: =SUBTOTAL(9,D13:D14) -> 46 | E15: =SUBTOTAL(9,E13:E14) -> 107.82 | F15: =SUBTOTAL(9,F13:F14) -> 2479.86
A16: 2714 | B16: Cobertor Manta Casal | C16: 44621 | D16: 29 | E16: 31.89 | F16: =D16*E16 -> 924.81
B17: Cobertor Manta Casal Total | D17: =SUBTOTAL(9,D16:D16) -> 29 | E17: =SUBTOTAL(9,E16:E16) -> 31.89 | F17: =SUBTOTAL(9,F16:F16) -> 924.81
A18: 19160 | B18: Colchão Casal de espuma | C18: 44599 | D18: 2 | E18: 733.9 | F18: =D18*E18 -> 1467.8
B19: Colchão Casal de espuma Total | D19: =SUBTOTAL(9,D18:D18) -> 2 | E19: =SUBTOTAL(9,E18:E18) -> 733.9 | F19: =SUBTOTAL(9,F18:F18) -> 1467.8
A20: 15632 | B20: Corset Corselet Underbust | C20: 44633 | D20: 18 | E20: 99.99 | F20: =D20*E20 -> 1799.82
B21: Corset Corselet Underbust Total | D21: =SUBTOTAL(9,D20:D20) -> 18 | E21: =SUBTOTAL(9,E20:E20) -> 99.99 | F21: =SUBTOTAL(9,F20:F20) -> 1799.82
A22: 13700 | B22: Headset gamer Knup KP-400 | C22: 44614 | D22: 12 | E22: 102 | F22: =D22*E22 -> 1224
B23: Headset gamer Knup KP-400 Total | D23: =SUBTOTAL(9,D22:D22) -> 12 | E23: =SUBTOTAL(9,E22:E22) -> 102 | F23: =SUBTOTAL(9,F22:F22) -> 1224
A24: 14264 | B24: Kit 120 Tangas | C24: 44587 | D24: 23 | E24: 165.6 | F24: =D24*E24 -> 3808.8
B25: Kit 120 Tangas Total | D25: =SUBTOTAL(9,D24:D24) -> 23 | E25: =SUBTOTAL(9,E24:E24) -> 165.6 | F25: =SUBTOTAL(9,F24:F24) -> 3808.8
A26: 2714 | B26: Kit 15 Tangas | C26: 44567 | D26: 23 | E26: 38.77 | F26: =D26*E26 -> 891.71
B27: Kit 15 Tangas Total | D27: =SUBTOTAL(9,D26:D26) -> 23 | E27: =SUBTOTAL(9,E26:E26) -> 38.77 | F27: =SUBTOTAL(9,F26:F26) -> 891.71
A28: 4820 | B28: Kit Bomba A Vácuo Para Vinho | C28: 44582 | D28: 20 | E28: 37.99 | F28: =D28*E28 -> 759.8
B29: Kit Bomba A Vácuo Para Vinho Total | D29: =SUBTOTAL(9,D28:D28) -> 20 | E29: =SUBTOTAL(9,E28:E28) -> 37.99 | F29: =SUBTOTAL(9,F28:F28) -> 759.8
A30: 4226 | B30: Kit De Acessórios Para Banheiro | C30: 44596 | D30: 45 | E30: 49 | F30: =D30*E30 -> 2205
B31: Kit De Acessórios Para Banheiro Total | D31: =SUBTOTAL(9,D30:D30) -> 45 | E31: =SUBTOTAL(9,E30:E30) -> 49 | F31: =SUBTOTAL(9,F30:F30) -> 2205
A32: 12630 | B32: LG K22 Dual SIM 32 GB | C32: 44605 | D32: 3 | E32: 999 | F32: =D32*E32 -> 2997
B33: LG K22 Dual SIM 32 GB Total | D33: =SUBTOTAL(9,D32:D32) -> 3 | E33: =SUBTOTAL(9,E32:E32) -> 999 | F33: =SUBTOTAL(9,F32:F32) -> 2997
A34: 17854 | B34: Moedor De Cafe Manual | C34: 44602 | D34: 4 | E34: 116.99 | F34: =D34*E34 -> 467.96
B35: Moedor De Cafe Manual Total | D35: =SUBTOTAL(9,D34:D34) -> 4 | E35: =SUBTOTAL(9,E34:E34) -> 116.99 | F35: =SUBTOTAL(9,F34:F34) -> 467.96
A36: 14624 | B36: Panela De Pressão | C36: 44562 | D36: 45 | E36: 56.99 | F36: =D36*E36 -> 2564.55
A37: 14624 | B37: Panela De Pressão | C37: 44674 | D37: 21 | E37: 56.99 | F37: =D37*E37 -> 1196.79
B38: Panela De Pressão Total | D38: =SUBTOTAL(9,D36:D37) -> 66 | E38: =SUBTOTAL(9,E36:E37) -> 113.98 | F38: =SUBTOTAL(9,F36:F37) -> 3761.34
A39: 9988 | B39: Panela De Pressão 4,5litros | C39: 44593 | D39: 31 | E39: 56.99 | F39: =D39*E39 -> 1766.69
B40: Panela De Pressão 4,5litros Total | D40: =SUBTOTAL(9,D39:D39) -> 31 | E40: =SUBTOTAL(9,E39:E39) -> 56.99 | F40: =SUBTOTAL(9,F39:F39) -> 1766.69
...

Sheet Planilha2
A1: Código Produto | B1: Produto | C1: Produto | D1: Meta
A2: 14624 | B2: =_xlfn.XLOOKUP(A2,Dados!A:A,Dados!B:B) -> Panela De Pressão | C2: =SUMIF(Dados!A:A,A2,Dados!F:F) -> 3761.34 | D2: =IF(C2>2000,"Meta batida","Em andamento") -> Meta batida
A3: 2714 | B3: =_xlfn.XLOOKUP(A3,Dados!A:A,Dados!B:B) -> Kit 15 Tangas | C3: =SUMIF(Dados!A:A,A3,Dados!F:F) -> 1816.52 | D3: =IF(C3>2000,"Meta batida","Em andamento") -> Em andamento
A4: 4550 | B4: =_xlfn.XLOOKUP(A4,Dados!A:A,Dados!B:B) -> Xiaomi Redmi 9 (Global) | C4: =SUMIF(Dados!A:A,A4,Dados!F:F) -> 14400 | D4: =IF(C4>2000,"Meta batida","Em andamento") -> Meta batida
A5: 7494 | B5: =_xlfn.XLOOKUP(A5,Dados!A:A,Dados!B:B) -> Terno Slim | C5: =SUMIF(Dados!A:A,A5,Dados!F:F) -> 46494 | D5: =IF(C5>2000,"Meta batida","Em andamento") -> Meta batida
A6: 4820 | B6: =_xlfn.XLOOKUP(A6,Dados!A:A,Dados!B:B) -> Kit Bomba A Vácuo Para Vinho | C6: =SUMIF(Dados!A:A,A6,Dados!F:F) -> 759.8 | D6: =IF(C6>2000,"Meta batida","Em andamento") -> Em andamento
A7: 14264 | B7: =_xlfn.XLOOKUP(A7,Dados!A:A,Dados!B:B) -> Kit 120 Tangas | C7: =SUMIF(Dados!A:A,A7,Dados!F:F) -> 3808.8 | D7: =IF(C7>2000,"Meta batida","Em andamento") -> Meta batida
A8: 9988 | B8: =_xlfn.XLOOKUP(A8,Dados!A:A,Dados!B:B) -> Panela De Pressão 4,5litros | C8: =SUMIF(Dados!A:A,A8,Dados!F:F) -> 1766.69 | D8: =IF(C8>2000,"Meta batida","Em andamento") -> Em andamento
A9: 4226 | B9: =_xlfn.XLOOKUP(A9,Dados!A:A,Dados!B:B) -> Kit De Acessórios Para Banheiro | C9: =SUMIF(Dados!A:A,A9,Dados!F:F) -> 2205 | D9: =IF(C9>2000,"Meta batida","Em andamento") -> Meta batida
A10: 19160 | B10: =_xlfn.XLOOKUP(A10,Dados!A:A,Dados!B:B) -> Colchão Casal de espuma | C10: =SUMIF(Dados!A:A,A10,Dados!F:F) -> 1467.8 | D10: =IF(C10>2000,"Meta batida","Em andamento") -> Em andamento
A11: 17854 | B11: =_xlfn.XLOOKUP(A11,Dados!A:A,Dados!B:B) -> Moedor De Cafe Manual | C11: =SUMIF(Dados!A:A,A11,Dados!F:F) -> 467.96 | D11: =IF(C11>2000,"Meta batida","Em andamento") -> Em andamento
A12: 12630 | B12: =_xlfn.XLOOKUP(A12,Dados!A:A,Dados!B:B) -> LG K22 Dual SIM 32 GB | C12: =SUMIF(Dados!A:A,A12,Dados!F:F) -> 2997 | D12: =IF(C12>2000,"Meta batida","Em andamento") -> Meta batida
A13: 17608 | B13: =_xlfn.XLOOKUP(A13,Dados!A:A,Dados!B:B) -> Spray Borrifador Pulverizador | C13: =SUMIF(Dados!A:A,A13,Dados!F:F) -> 209.4 | D13: =IF(C13>2000,"Meta batida","Em andamento") -> Em andamento
... A22: 2345 | B22: =_xlfn.XLOOKUP(A22,Dados!A:A,Dados!B:B) -> Caixa de ferramentas Fercar | C22: =SUMIF(Dados!A:A,A22,Dados!F:F) -> 3005.52 | D22: =IF(C22>2000,"Meta batida","Em andamento") -> Meta batida
